<robot xmlns:xacro="http://ros.org/wiki/xacro">
  <joint name="base_link__link1" type="revolute">
    <parent link="base_link"/>
    <child link="link1"/>
    <origin rpy="0 0 0" xyz="0.0 0.0 0.0065"/>
    <axis xyz="0.0 0.0 1.0"/>
    <limit effort="1" lower="-3.1415" upper="3.1415" velocity="10.0"/>
  </joint>

  <joint name="link1__link2" type="revolute">
    <parent link="link1"/>
    <child link="link2"/>
    <origin rpy="0 0 0" xyz="0.0 0.0 0.0170"/>
    <axis xyz="0.0 1.0 0.0"/>
    <limit effort="1" lower="-3.1415" upper="3.1415" velocity="10.0"/>
  </joint>

  <joint name="link2__link3" type="revolute">
    <parent link="link2"/>
    <child link="link3"/>
    <origin rpy="0 0 0" xyz="0.0 0.0 0.055"/>
    <axis xyz="1.0 0.0 0.0"/>
    <limit effort="1" lower="-3.1415" upper="3.1415" velocity="10.0"/>
  </joint>

  <joint name="link3__camera" type="fixed">
    <parent link="link3"/>
    <child link="camera"/>
    <origin rpy="0 0 0" xyz="0.0648 0 0"/>
  </joint>

  <joint name="camera__camera_optical" type="fixed">
    <parent link="camera"/>
    <child link="camera_optical"/>
    <origin rpy="-1.57 0 -1.57" xyz="0 0 0"/>
  </joint>
</robot>
